Traceback (most recent call last):
  File "manage.py", line 8, in <module>
    from django.core.management import execute_from_command_line
ModuleNotFoundError: No module named 'django'

The above exception was the direct cause of the following exception:

Traceback (most recent call last):
  File "manage.py", line 14, in <module>
    ) from exc
ImportError: Couldn't import Django. Are you sure it's installed and available on your PYTHONPATH environment variable? Did you forget to activate a virtual environment?
Traceback (most recent call last):
  File "manage.py", line 8, in <module>
    from django.core.management import execute_from_command_line
ModuleNotFoundError: No module named 'django'

The above exception was the direct cause of the following exception:

Traceback (most recent call last):
  File "manage.py", line 14, in <module>
    ) from exc
ImportError: Couldn't import Django. Are you sure it's installed and available on your PYTHONPATH environment variable? Did you forget to activate a virtual environment?
Traceback (most recent call last):
  File "manage.py", line 8, in <module>
    from django.core.management import execute_from_command_line
ModuleNotFoundError: No module named 'django'

The above exception was the direct cause of the following exception:

Traceback (most recent call last):
  File "manage.py", line 14, in <module>
    ) from exc
ImportError: Couldn't import Django. Are you sure it's installed and available on your PYTHONPATH environment variable? Did you forget to activate a virtual environment?
Traceback (most recent call last):
  File "manage.py", line 8, in <module>
    from django.core.management import execute_from_command_line
ModuleNotFoundError: No module named 'django'

The above exception was the direct cause of the following exception:

Traceback (most recent call last):
  File "manage.py", line 14, in <module>
    ) from exc
ImportError: Couldn't import Django. Are you sure it's installed and available on your PYTHONPATH environment variable? Did you forget to activate a virtual environment?
Traceback (most recent call last):
  File "manage.py", line 8, in <module>
    from django.core.management import execute_from_command_line
ModuleNotFoundError: No module named 'django'

The above exception was the direct cause of the following exception:

Traceback (most recent call last):
  File "manage.py", line 14, in <module>
    ) from exc
ImportError: Couldn't import Django. Are you sure it's installed and available on your PYTHONPATH environment variable? Did you forget to activate a virtual environment?
[17/Mar/2019 00:35:49] "GET /e/wangx308 HTTP/1.1" 301 0
[17/Mar/2019 00:35:49] "GET /e/wangx308/ HTTP/1.1" 200 37
[17/Mar/2019 00:45:15] "GET /e/wangx308 HTTP/1.1" 301 0
[17/Mar/2019 00:45:15] "GET /e/wangx308/ HTTP/1.1" 200 37
[17/Mar/2019 01:39:05] "POST /e/wangx308/lab7/ HTTP/1.1" 200 13
[17/Mar/2019 01:58:10] "POST /e/wangx308/lab7/ HTTP/1.1" 200 13
[17/Mar/2019 01:58:10] "POST /e/wangx308/lab7/ HTTP/1.1" 200 13
[17/Mar/2019 01:58:12] "POST /e/wangx308/lab7/ HTTP/1.1" 200 13
[17/Mar/2019 01:58:12] "POST /e/wangx308/lab7/ HTTP/1.1" 200 13
[17/Mar/2019 01:58:12] "POST /e/wangx308/lab7/ HTTP/1.1" 200 13
[17/Mar/2019 01:58:12] "POST /e/wangx308/lab7/ HTTP/1.1" 200 13
[17/Mar/2019 02:08:07] "POST /e/wangx308/lab7/ HTTP/1.1" 200 13
[17/Mar/2019 02:08:08] "POST /e/wangx308/lab7/ HTTP/1.1" 200 13
Performing system checks...

System check identified no issues (0 silenced).

You have 15 unapplied migration(s). Your project may not work properly until you apply the migrations for app(s): admin, auth, contenttypes, sessions.
Run 'python manage.py migrate' to apply them.
March 17, 2019 - 00:34:44
Django version 2.1.7, using settings 'django_project.settings'
Starting development server at http://localhost:10059/
Quit the server with CONTROL-C.
Unhandled exception in thread started by <function check_errors.<locals>.wrapper at 0x7f0410d512f0>
Traceback (most recent call last):
  File "/home/wangx308/CS1XA3/python_env/lib/python3.6/site-packages/django/utils/autoreload.py", line 225, in wrapper
    fn(*args, **kwargs)
  File "/home/wangx308/CS1XA3/python_env/lib/python3.6/site-packages/django/core/management/commands/runserver.py", line 117, in inner_run
    self.check(display_num_errors=True)
  File "/home/wangx308/CS1XA3/python_env/lib/python3.6/site-packages/django/core/management/base.py", line 379, in check
    include_deployment_checks=include_deployment_checks,
  File "/home/wangx308/CS1XA3/python_env/lib/python3.6/site-packages/django/core/management/base.py", line 366, in _run_checks
    return checks.run_checks(**kwargs)
  File "/home/wangx308/CS1XA3/python_env/lib/python3.6/site-packages/django/core/checks/registry.py", line 71, in run_checks
    new_errors = check(app_configs=app_configs)
  File "/home/wangx308/CS1XA3/python_env/lib/python3.6/site-packages/django/core/checks/urls.py", line 40, in check_url_namespaces_unique
    all_namespaces = _load_all_namespaces(resolver)
  File "/home/wangx308/CS1XA3/python_env/lib/python3.6/site-packages/django/core/checks/urls.py", line 57, in _load_all_namespaces
    url_patterns = getattr(resolver, 'url_patterns', [])
  File "/home/wangx308/CS1XA3/python_env/lib/python3.6/site-packages/django/utils/functional.py", line 37, in __get__
    res = instance.__dict__[self.name] = self.func(instance)
  File "/home/wangx308/CS1XA3/python_env/lib/python3.6/site-packages/django/urls/resolvers.py", line 533, in url_patterns
    patterns = getattr(self.urlconf_module, "urlpatterns", self.urlconf_module)
  File "/home/wangx308/CS1XA3/python_env/lib/python3.6/site-packages/django/utils/functional.py", line 37, in __get__
    res = instance.__dict__[self.name] = self.func(instance)
  File "/home/wangx308/CS1XA3/python_env/lib/python3.6/site-packages/django/urls/resolvers.py", line 526, in urlconf_module
    return import_module(self.urlconf_name)
  File "/home/wangx308/CS1XA3/python_env/lib/python3.6/importlib/__init__.py", line 126, in import_module
    return _bootstrap._gcd_import(name[level:], package, level)
  File "<frozen importlib._bootstrap>", line 994, in _gcd_import
  File "<frozen importlib._bootstrap>", line 971, in _find_and_load
  File "<frozen importlib._bootstrap>", line 955, in _find_and_load_unlocked
  File "<frozen importlib._bootstrap>", line 665, in _load_unlocked
  File "<frozen importlib._bootstrap_external>", line 678, in exec_module
  File "<frozen importlib._bootstrap>", line 219, in _call_with_frames_removed
  File "/home/wangx308/CS1XA3/python_env/django_project/django_project/urls.py", line 38, in <module>
    path('e/wangx308/lab7/' , verify_password)
NameError: name 'verify_password' is not defined
Performing system checks...

Performing system checks...

System check identified no issues (0 silenced).

You have 15 unapplied migration(s). Your project may not work properly until you apply the migrations for app(s): admin, auth, contenttypes, sessions.
Run 'python manage.py migrate' to apply them.
March 17, 2019 - 02:12:21
Django version 2.1.7, using settings 'django_project.settings'
Starting development server at http://localhost:10059/
Quit the server with CONTROL-C.
Performing system checks...

System check identified no issues (0 silenced).

You have 15 unapplied migration(s). Your project may not work properly until you apply the migrations for app(s): admin, auth, contenttypes, sessions.
Run 'python manage.py migrate' to apply them.
March 17, 2019 - 02:12:32
Django version 2.1.7, using settings 'django_project.settings'
Starting development server at http://localhost:10059/
Quit the server with CONTROL-C.
[18/Mar/2019 22:23:18] "GET /e/wangx308/ HTTP/1.1" 200 37
[18/Mar/2019 22:40:35] "GET /e/wangx308 HTTP/1.1" 301 0
[18/Mar/2019 22:40:35] "GET /e/wangx308/ HTTP/1.1" 200 37
[18/Mar/2019 22:40:40] "GET /e/wangx308/lab7 HTTP/1.1" 301 0
[18/Mar/2019 22:40:40] "GET /e/wangx308/lab7/ HTTP/1.1" 200 13
[18/Mar/2019 22:41:06] "POST /e/wangx308/lab7/ HTTP/1.1" 200 13
[18/Mar/2019 22:41:10] "POST /e/wangx308/lab7/ HTTP/1.1" 200 13
[18/Mar/2019 22:41:27] "POST /e/wangx308/lab7/ HTTP/1.1" 200 4
[18/Mar/2019 22:41:28] "POST /e/wangx308/lab7/ HTTP/1.1" 200 4
[18/Mar/2019 22:41:29] "POST /e/wangx308/lab7/ HTTP/1.1" 200 4
[26/Mar/2019 02:54:16] "GET /e/wangx308 HTTP/1.1" 301 0
[26/Mar/2019 02:54:16] "GET /e/wangx308/ HTTP/1.1" 200 37
[26/Mar/2019 02:54:47] "GET /e/wangx308/ HTTP/1.1" 200 37
